python3 main_finetune.py --seed 0 --downstream_task classification --jitter_sigma 0.2 --rescaling_sigma 0.5 --ft_surr_phase_noise 0.075 --input_channels 1 --input_electrodes 12 --time_steps 2500 --patch_height 1 --patch_width 100 --model vit_tiny_patchX --batch_size 8 --epochs 400 --patience 25 --max_delta 0.25 --accum_iter 1 --drop_path 0.2 --weight_decay 0.2 --layer_decay 0.5 --min_lr 0.0 --blr 3e-6 --warmup_epoch 5 --smoothing 0.1 --data_path /home/nadja/ECG/data/tensors/tensor.pt --labels_path /home/nadja/ECG/data/labels/labels.pt --val_data_path /home/nadja/ECG/data/tensors/tensor.pt --val_labels_path /home/nadja/ECG/data/labels/labels.pt --nb_classes 2 --log_dir /home/nadja/ECG_new/ --num_workers 24 --finetune /home/nadja/ECG_new//MMCL-ECG-CMR/model_weights/signal_encoder_mmcl_wo_mdm.pth --pos_label 1 --global_pool --attention_pool --wandb --wandb_project MAE_ECG_Fin_Tiny_LV --output_dir /home/nadja/ECG_new//weights/
wandb: Currently logged in as: madja161n. Use `wandb login --relogin` to force relogin
wandb: ERROR Error while calling W&B API: permission denied (<Response [403]>)
Thread SenderThread:
Traceback (most recent call last):
  File "/home/nadja/.conda/envs/mae/lib/python3.10/site-packages/wandb/sdk/lib/retry.py", line 113, in __call__
    result = self._call_fn(*args, **kwargs)
  File "/home/nadja/.conda/envs/mae/lib/python3.10/site-packages/wandb/sdk/internal/internal_api.py", line 204, in execute
    return self.client.execute(*args, **kwargs)  # type: ignore
  File "/home/nadja/.conda/envs/mae/lib/python3.10/site-packages/wandb/vendor/gql-0.2.0/wandb_gql/client.py", line 52, in execute
    result = self._get_result(document, *args, **kwargs)
  File "/home/nadja/.conda/envs/mae/lib/python3.10/site-packages/wandb/vendor/gql-0.2.0/wandb_gql/client.py", line 60, in _get_result
    return self.transport.execute(document, *args, **kwargs)
  File "/home/nadja/.conda/envs/mae/lib/python3.10/site-packages/wandb/vendor/gql-0.2.0/wandb_gql/transport/requests.py", line 39, in execute
    request.raise_for_status()
  File "/home/nadja/.conda/envs/mae/lib/python3.10/site-packages/requests/models.py", line 1021, in raise_for_status
    raise HTTPError(http_error_msg, response=self)
requests.exceptions.HTTPError: 403 Client Error: Forbidden for url: https://api.wandb.ai/graphql

During handling of the above exception, another exception occurred:

Traceback (most recent call last):
  File "/home/nadja/.conda/envs/mae/lib/python3.10/site-packages/wandb/apis/normalize.py", line 25, in wrapper
    return func(*args, **kwargs)
  File "/home/nadja/.conda/envs/mae/lib/python3.10/site-packages/wandb/sdk/internal/internal_api.py", line 1465, in upsert_run
    response = self.gql(
  File "/home/nadja/.conda/envs/mae/lib/python3.10/site-packages/wandb/sdk/lib/retry.py", line 129, in __call__
    retry_timedelta_triggered = check_retry_fn(e)
  File "/home/nadja/.conda/envs/mae/lib/python3.10/site-packages/wandb/util.py", line 942, in check_retry_fn
    return fallback_retry_fn(e)
  File "/home/nadja/.conda/envs/mae/lib/python3.10/site-packages/wandb/util.py", line 889, in no_retry_auth
    raise CommError("Permission denied, ask the project owner to grant you access")
wandb.errors.CommError: Permission denied, ask the project owner to grant you access

During handling of the above exception, another exception occurred:

Traceback (most recent call last):
  File "/home/nadja/.conda/envs/mae/lib/python3.10/site-packages/wandb/sdk/internal/internal_util.py", line 51, in run
    self._run()
  File "/home/nadja/.conda/envs/mae/lib/python3.10/site-packages/wandb/sdk/internal/internal_util.py", line 102, in _run
    self._process(record)
  File "/home/nadja/.conda/envs/mae/lib/python3.10/site-packages/wandb/sdk/internal/internal.py", line 310, in _process
    self._sm.send(record)
  File "/home/nadja/.conda/envs/mae/lib/python3.10/site-packages/wandb/sdk/internal/sender.py", line 304, in send
    send_handler(record)
  File "/home/nadja/.conda/envs/mae/lib/python3.10/site-packages/wandb/sdk/internal/sender.py", line 782, in send_run
    self._init_run(run, config_value_dict)
  File "/home/nadja/.conda/envs/mae/lib/python3.10/site-packages/wandb/sdk/internal/sender.py", line 808, in _init_run
    server_run, inserted, server_messages = self._api.upsert_run(
  File "/home/nadja/.conda/envs/mae/lib/python3.10/site-packages/wandb/apis/normalize.py", line 61, in wrapper
    raise CommError(message, err).with_traceback(sys.exc_info()[2])
  File "/home/nadja/.conda/envs/mae/lib/python3.10/site-packages/wandb/apis/normalize.py", line 25, in wrapper
    return func(*args, **kwargs)
  File "/home/nadja/.conda/envs/mae/lib/python3.10/site-packages/wandb/sdk/internal/internal_api.py", line 1465, in upsert_run
    response = self.gql(
  File "/home/nadja/.conda/envs/mae/lib/python3.10/site-packages/wandb/sdk/lib/retry.py", line 129, in __call__
    retry_timedelta_triggered = check_retry_fn(e)
  File "/home/nadja/.conda/envs/mae/lib/python3.10/site-packages/wandb/util.py", line 942, in check_retry_fn
    return fallback_retry_fn(e)
  File "/home/nadja/.conda/envs/mae/lib/python3.10/site-packages/wandb/util.py", line 889, in no_retry_auth
    raise CommError("Permission denied, ask the project owner to grant you access")
wandb.errors.CommError: Permission denied, ask the project owner to grant you access
wandb: ERROR Internal wandb error: file data was not synced
wandb: ERROR Error communicating with wandb process
wandb: ERROR For more info see: https://docs.wandb.ai/library/init#init-start-error
job dir: /home/nadja/ECG_new/MMCL-ECG-CMR/mae/mae
Namespace(lower_bnd=0,
upper_bnd=0,
batch_size=8,
epochs=400,
accum_iter=1,
model='vit_tiny_patchX',
input_channels=1,
input_electrodes=12,
time_steps=2500,
input_size=(1,
12,
2500),
patch_height=1,
patch_width=100,
patch_size=(1,
100),
drop_path=0.2,
masking_blockwise=False,
mask_ratio=0.0,
mask_c_ratio=0.0,
mask_t_ratio=0.0,
jitter_sigma=0.2,
rescaling_sigma=0.5,
ft_surr_phase_noise=0.075,
freq_shift_delta=0.005,
color_jitter=None,
aa='rand-m9-mstd0.5-inc1',
clip_grad=None,
weight_decay=0.2,
lr=None,
blr=3e-06,
layer_decay=0.5,
min_lr=0.0,
warmup_epochs=5,
patience=25.0,
max_delta=0.25,
smoothing=0.1,
reprob=0.25,
remode='pixel',
recount=1,
resplit=False,
mixup=0,
cutmix=0,
cutmix_minmax=None,
mixup_prob=1.0,
mixup_switch_prob=0.5,
mixup_mode='batch',
finetune='/home/nadja/ECG_new//MMCL-ECG-CMR/model_weights/signal_encoder_mmcl_wo_mdm.pth',
global_pool='attention_pool',
attention_pool=True,
downstream_task='classification',
data_path='/home/nadja/ECG/data/tensors/tensor.pt',
labels_path='/home/nadja/ECG/data/labels/labels.pt',
labels_mask_path='',
val_data_path='/home/nadja/ECG/data/tensors/tensor.pt',
val_labels_path='/home/nadja/ECG/data/labels/labels.pt',
val_labels_mask_path='',
nb_classes=2,
pos_label=1,
output_dir='/home/nadja/ECG_new//weights/',
log_dir='/home/nadja/ECG_new/',
wandb=True,
wandb_project='MAE_ECG_Fin_Tiny_LV',
wandb_id='',
device='cuda',
seed=0,
resume='',
plot_attention_map=False,
plot_embeddings=False,
embeddings_dir='',
predictions_dir='',
start_epoch=0,
eval=False,
dist_eval=False,
num_workers=24,
pin_mem=True,
world_size=1,
local_rank=-1,
dist_on_itp=False,
dist_url='env://',
distributed=False)
Training set size:  100
Validation set size:  100
Sampler_train = <torch.utils.data.distributed.DistributedSampler object at 0x7fb4c610c100>
Problem at: /home/nadja/ECG_new/MMCL-ECG-CMR/mae/mae/main_finetune.py 326 main
Traceback (most recent call last):
  File "/home/nadja/ECG_new/MMCL-ECG-CMR/mae/mae/main_finetune.py", line 572, in <module>
    main(args)
  File "/home/nadja/ECG_new/MMCL-ECG-CMR/mae/mae/main_finetune.py", line 326, in main
    wandb.init(project=args.wandb_project, config=config, entity="oturgut")
  File "/home/nadja/.conda/envs/mae/lib/python3.10/site-packages/wandb/sdk/wandb_init.py", line 1043, in init
    run = wi.init()
  File "/home/nadja/.conda/envs/mae/lib/python3.10/site-packages/wandb/sdk/wandb_init.py", line 691, in init
    raise UsageError(error_message)
wandb.errors.UsageError: Error communicating with wandb process
For more info see: https://docs.wandb.ai/library/init#init-start-error
